Workbook

Sheet Summary
A1: Line | B1: Detail | C1: Transactions | D1: Amount (USD)
A2: OPENING BALANCE — 1 January 2025 | B2: Mercury's own ending balance on the statement for 01–31 December 2024 | D2: 11053.84
A4: MONEY IN
A5: Incoming wires | B5: Domestic and international client and affiliate receipts | C5: 13 | D5: 35757.76
A6: Other incoming (ACH credits) | B6: YouTube partner payments, an affiliate ACH credit and account-verification micro-deposits | C6: 7 | D6: 967.47
A7: Mercury IO card cashback | B7: Cashback credited to the checking account | C7: 2 | D7: 4.82
A8: TOTAL MONEY IN | C8: =SUM(C5:C7) -> 22 | D8: =SUM(D5:D7) -> 36730.05
A10: MONEY OUT
A11: Outgoing payments | B11: Google Ads invoices, accountancy and platform fees | C11: 9 | D11: -15341.23
A12: Sent to the Mercury IO card | B12: Autopay moving cash out of the bank to settle the credit card | C12: 2 | D12: -322.15
A13: TOTAL MONEY OUT | B13: Every dollar that left the bank, card payments included | C13: =SUM(C11:C12) -> 11 | D13: =SUM(D11:D12) -> -15663.38
A15: NET CHANGE FOR THE YEAR | B15: Total money in less total money out | C15: 33 | D15: =D8+D13 -> 21066.67
A17: CLOSING BALANCE — 31 December 2025 | B17: Mercury's own ending balance on the statement for 01–31 December 2025 | D17: =D2+D15 -> 32120.51
A19: PEAK BALANCE — 31 July 2025 | B19: Highest balance held at any point in 2025 — the maximum of the Daily sheet | D19: =MAX(Daily!E2:E366) -> 35157.93
A21: Total expense incurred in 2025 | B21: Outgoing payments plus what the card itself spent — see the Reconciliation sheet | C21: 12 | D21: -15663.38

Sheet Peak
A1: Measure | B1: Detail | C1: Date | D1: Amount (USD)
A2: PEAK BALANCE | B2: Highest end-of-day balance across all 365 days of 2025 | C2: 31 July 2025 | D2: =MAX(Daily!E2:E366) -> 35157.93
A4: Reached on | B4: The day the balance first closed at that figure | C4: 31 July 2025 | D4: =D2 -> 35157.93
A5: Held until | B5: It stayed there for 4 days; the next movement was the first debit after it | C5: 3 August 2025 | D5: =D2 -> 35157.93
A6: Tipped to the peak by | B6: CLICKSTACK LTD. — Incoming wire (international). The marginal credit that set the exact maximum, not what built it. | C6: 31 July 2025 | D6: 750
A7: Balance immediately before | B7: Where the balance stood the moment before that credit landed | C7: 31 July 2025 | D7: =D2-D6 -> 34407.93
A8: Next movement after the peak | B8: Google LLC — Outgoing payment | C8: 4 August 2025 | D8: -6600.54
A9: Balance after that movement | B9: Where the balance sat once the peak broke | C9: 4 August 2025 | D9: =D2+D8 -> 28557.39
A11: Intra-day high | B11: Highest point at any moment, in Mercury's own posting order — the same figure | C11: 31 July 2025 | D11: =D2 -> 35157.93
A13: Lowest balance of the year | B13: Held 6 days — and it is the opening balance: no day closed below where the year began | C13: 1 January 2025 – 6 January 2025 | D13: =MIN(Daily!E2:E366) -> 11053.84
A14: Average daily balance | B14: Mean of all 365 end-of-day balances | C14: 1 Jan – 31 Dec 2025 | D14: =AVERAGE(Daily!E2:E366) -> 26110.17
A15: Opening balance | B15: 1 January 2025 | C15: 1 January 2025 | D15: =Summary!D2 -> 11053.84
A16: Closing balance | B16: 31 December 2025 | C16: 31 December 2025 | D16: =Summary!D17 -> 32120.51
A17: Peak above closing | B17: How far the peak sat above where the year ended | D17: =D2-D16 -> 3037.42
A18: Peak above opening | B18: How far the peak sat above where the year began | D18: =D2-D15 -> 24104.09
A20: Days closing at or above $35,000 | B20: How many of the 365 days closed at or above that level | C20: 4 days
A21: Days closing at or above $30,000 | C21: 146 days
A22: Days closing at or above $25,000 | C22: 274 days
A24: WHICH CLOCK THIS IS ON | B24: Every date here is UTC — the clock all 24 of Mercury's own statements reconcile on
A25: Margin at the start of the year | B25: Hours between 1 Jan 2025 00:00 UTC and the nearest transaction either side | C25: 163.57 hours
A26: Margin at the end of the year | B26: Hours to the nearest transaction either side — wider than any timezone, so the closing balance is the same on every clock | C26: 12.01 hours
A27: Margin on the PEAK DATE | B27: The peak AMOUNT is the same on any clock, the DATE is not — see the Reconciliation sheet | C27: 2.03 hours
A29: PEAK BY MONTH | B29: Highest end-of-day balance inside each month
A30: January 2025 | C30: 7 January 2025 | D30: =MAX(Daily!E2:E32) -> 13303.84
A31: February 2025 | C31: 1 February 2025 | D31: =MAX(Daily!E33:E60) -> 13303.84
A32: March 2025 | C32: 26 March 2025 | D32: =MAX(Daily!E61:E91) -> 16985.4
A33: April 2025 | C33: 7 April 2025 | D33: =MAX(Daily!E92:E121) -> 28997.24
A34: May 2025 | C34: 1 May 2025 | D34: =MAX(Daily!E122:E152) -> 28996.2
A35: June 2025 | C35: 27 June 2025 | D35: =MAX(Daily!E153:E182) -> 29323.2
A36: July 2025 | C36: 31 July 2025 | D36: =MAX(Daily!E183:E213) -> 35157.93
A37: August 2025 | C37: 1 August 2025 | D37: =MAX(Daily!E214:E244) -> 35157.93
A38: September 2025 | C38: 22 September 2025 | D38: =MAX(Daily!E245:E274) -> 34248.63
A39: October 2025 | C39: 1 October 2025 | D39: =MAX(Daily!E275:E305) -> 34248.63
A40: November 2025 | C40: 21 November 2025 | D40: =MAX(Daily!E306:E335) -> 30713.57
A41: December 2025 | C41: 31 December 2025 | D41: =MAX(Daily!E336:E366) -> 32120.51

Sheet Daily
A1: Date | B1: Day | C1: Movements | D1: Moved that day (USD) | E1: End-of-day balance (USD) | F1: Note
A2: 2025-01-01 | B2: Wed | C2: 0 | E2: =Summary!D2+D2 -> 11053.84 | F2: LOW
A3: 2025-01-02 | B3: Thu | C3: 0 | E3: =E2+D3 -> 11053.84 | F3: low held
A4: 2025-01-03 | B4: Fri | C4: 0 | E4: =E3+D4 -> 11053.84 | F4: low held
A5: 2025-01-04 | B5: Sat | C5: 0 | E5: =E4+D5 -> 11053.84 | F5: low held
A6: 2025-01-05 | B6: Sun | C6: 0 | E6: =E5+D6 -> 11053.84 | F6: low held
A7: 2025-01-06 | B7: Mon | C7: 0 | E7: =E6+D7 -> 11053.84 | F7: low held
A8: 2025-01-07 | B8: Tue | C8: 1 | D8: 2250 | E8: =E7+D8 -> 13303.84
A9: 2025-01-08 | B9: Wed | C9: 0 | E9: =E8+D9 -> 13303.84
A10: 2025-01-09 | B10: Thu | C10: 0 | E10: =E9+D10 -> 13303.84
A11: 2025-01-10 | B11: Fri | C11: 0 | E11: =E10+D11 -> 13303.84
A12: 2025-01-11 | B12: Sat | C12: 0 | E12: =E11+D12 -> 13303.84
A13: 2025-01-12 | B13: Sun | C13: 0 | E13: =E12+D13 -> 13303.84
A14: 2025-01-13 | B14: Mon | C14: 0 | E14: =E13+D14 -> 13303.84
A15: 2025-01-14 | B15: Tue | C15: 0 | E15: =E14+D15 -> 13303.84
A16: 2025-01-15 | B16: Wed | C16: 0 | E16: =E15+D16 -> 13303.84
A17: 2025-01-16 | B17: Thu | C17: 0 | E17: =E16+D17 -> 13303.84
A18: 2025-01-17 | B18: Fri | C18: 0 | E18: =E17+D18 -> 13303.84
A19: 2025-01-18 | B19: Sat | C19: 0 | E19: =E18+D19 -> 13303.84
A20: 2025-01-19 | B20: Sun | C20: 0 | E20: =E19+D20 -> 13303.84
... A72: 2025-03-12 | B72: Wed | C72: 0 | E72: =E71+D72 -> 13303.84
A73: 2025-03-13 | B73: Thu | C73: 1 | D73: -16.58 | E73: =E72+D73 -> 13287.26
A74: 2025-03-14 | B74: Fri | C74: 0 | E74: =E73+D74 -> 13287.26
A75: 2025-03-15 | B75: Sat | C75: 0 | E75: =E74+D75 -> 13287.26
A76: 2025-03-16 | B76: Sun | C76: 0 | E76: =E75+D76 -> 13287.26
A77: 2025-03-17 | B77: Mon | C77: 0 | E77: =E76+D77 -> 13287.26
A78: 2025-03-18 | B78: Tue | C78: 0 | E78: =E77+D78 -> 13287.26
A79: 2025-03-19 | B79: Wed | C79: 0 | E79: =E78+D79 -> 13287.26
A80: 2025-03-20 | B80: Thu | C80: 0 | E80: =E79+D80 -> 13287.26
A81: 2025-03-21 | B81: Fri | C81: 0 | E81: =E80+D81 -> 13287.26
A82: 2025-03-22 | B82: Sat | C82: 0 | E82: =E81+D82 -> 13287.26
A83: 2025-03-23 | B83: Sun | C83: 0 | E83: =E82+D83 -> 13287.26
A84: 2025-03-24 | B84: Mon | C84: 1 | D84: -90 | E84: =E83+D84 -> 13197.26
A85: 2025-03-25 | B85: Tue | C85: 0 | E85: =E84+D85 -> 13197.26
A86: 2025-03-26 | B86: Wed | C86: 1 | D86: 3788.14 | E86: =E85+D86 -> 16985.4
A87: 2025-03-27 | B87: Thu | C87: 0 | E87: =E86+D87 -> 16985.4
A88: 2025-03-28 | B88: Fri | C88: 0 | E88: =E87+D88 -> 16985.4
A89: 2025-03-29 | B89: Sat | C89: 0 | E89: =E88+D89 -> 16985.4
A90: 2025-03-30 | B90: Sun | C90: 0 | E90: =E89+D90 -> 16985.4
A91: 2025-03-31 | B91: Mon | C91: 0 | E91: =E90+D91 -> 16985.4
...

Sheet Monthly
A1: Month | B1: Opening | C1: Money in | D1: Money out | E1: Net | F1: Closing | G1: Statement | H1: Check | I1: Peak in month | J1: Peak date | K1: Txns
A2: January 2025 | B2: =Summary!D2 -> 11053.84 | C2: 2250 | D2: 0 | E2: =C2+D2 -> 2250 | F2: =B2+E2 -> 13303.84 | G2: 13303.84 | H2: =IF(F2=G2,"MATCH","MISMATCH") -> MATCH | I2: =MAX(Daily!E2:E32) -> 13303.84 | J2: 2025-01-07 | K2: 1
A3: February 2025 | B3: =F2 -> 13303.84 | C3: 0 | D3: 0 | E3: =C3+D3 -> 0 | F3: =B3+E3 -> 13303.84 | G3: 13303.84 | H3: =IF(F3=G3,"MATCH","MISMATCH") -> MATCH | I3: =MAX(Daily!E33:E60) -> 13303.84 | J3: 2025-02-01 | K3: 0
A4: March 2025 | B4: =F3 -> 13303.84 | C4: 3788.14 | D4: -106.58 | E4: =C4+D4 -> 3681.56 | F4: =B4+E4 -> 16985.4 | G4: 16985.4 | H4: =IF(F4=G4,"MATCH","MISMATCH") -> MATCH | I4: =MAX(Daily!E61:E91) -> 16985.4 | J4: 2025-03-26 | K4: 3
A5: April 2025 | B5: =F4 -> 16985.4 | C5: 12011.88 | D5: -1.08 | E5: =C5+D5 -> 12010.8 | F5: =B5+E5 -> 28996.2 | G5: 28996.2 | H5: =IF(F5=G5,"MATCH","MISMATCH") -> MATCH | I5: =MAX(Daily!E92:E121) -> 28997.24 | J5: 2025-04-07 | K5: 5
A6: May 2025 | B6: =F5 -> 28996.2 | C6: 0 | D6: 0 | E6: =C6+D6 -> 0 | F6: =B6+E6 -> 28996.2 | G6: 28996.2 | H6: =IF(F6=G6,"MATCH","MISMATCH") -> MATCH | I6: =MAX(Daily!E122:E152) -> 28996.2 | J6: 2025-05-01 | K6: 0
A7: June 2025 | B7: =F6 -> 28996.2 | C7: 327 | D7: -6.44 | E7: =C7+D7 -> 320.56 | F7: =B7+E7 -> 29316.76 | G7: 29316.76 | H7: =IF(F7=G7,"MATCH","MISMATCH") -> MATCH | I7: =MAX(Daily!E153:E182) -> 29323.2 | J7: 2025-06-27 | K7: 2
A8: July 2025 | B8: =F7 -> 29316.76 | C8: 8481.39 | D8: -2640.22 | E8: =C8+D8 -> 5841.17 | F8: =B8+E8 -> 35157.93 | G8: 35157.93 | H8: =IF(F8=G8,"MATCH","MISMATCH") -> MATCH | I8: =MAX(Daily!E183:E213) -> 35157.93 | J8: 2025-07-31 | K8: 6
A9: August 2025 | B9: =F8 -> 35157.93 | C9: 2143.18 | D9: -6600.54 | E9: =C9+D9 -> -4457.36 | F9: =B9+E9 -> 30700.57 | G9: 30700.57 | H9: =IF(F9=G9,"MATCH","MISMATCH") -> MATCH | I9: =MAX(Daily!E214:E244) -> 35157.93 | J9: 2025-08-01 | K9: 4
A10: September 2025 | B10: =F9 -> 30700.57 | C10: 5908.02 | D10: -2359.96 | E10: =C10+D10 -> 3548.06 | F10: =B10+E10 -> 34248.63 | G10: 34248.63 | H10: =IF(F10=G10,"MATCH","MISMATCH") -> MATCH | I10: =MAX(Daily!E245:E274) -> 34248.63 | J10: 2025-09-22 | K10: 5
A11: October 2025 | B11: =F10 -> 34248.63 | C11: 141.39 | D11: -3774.6 | E11: =C11+D11 -> -3633.21 | F11: =B11+E11 -> 30615.42 | G11: 30615.42 | H11: =IF(F11=G11,"MATCH","MISMATCH") -> MATCH | I11: =MAX(Daily!E275:E305) -> 34248.63 | J11: 2025-10-01 | K11: 2
A12: November 2025 | B12: =F11 -> 30615.42 | C12: 179.05 | D12: -80.9 | E12: =C12+D12 -> 98.15 | F12: =B12+E12 -> 30713.57 | G12: 30713.57 | H12: =IF(F12=G12,"MATCH","MISMATCH") -> MATCH | I12: =MAX(Daily!E306:E335) -> 30713.57 | J12: 2025-11-21 | K12: 3
A13: December 2025 | B13: =F12 -> 30713.57 | C13: 1500 | D13: -93.06 | E13: =C13+D13 -> 1406.94 | F13: =B13+E13 -> 32120.51 | G13: 32120.51 | H13: =IF(F13=G13,"MATCH","MISMATCH") -> MATCH | I13: =MAX(Daily!E336:E366) -> 32120.51 | J13: 2025-12-31 | K13: 2
A14: FULL YEAR 2025 | B14: =Summary!D2 -> 11053.84 | C14: =SUM(C2:C13) -> 36730.05 | D14: =SUM(D2:D13) -> -15663.38 | E14: =C14+D14 -> 21066.67 | F14: =B14+E14 -> 32120.51 | G14: =F13 -> 32120.51 | H14: =IF(F14=G14,"MATCH","MISMATCH") -> MATCH | I14: =MAX(Daily!E2:E366) -> 35157.93 | J14: 2025-07-31 | K14: =SUM(K2:K13) -> 33

Sheet Ledger
A1: Posted | B1: Account | C1: Type | D1: Counterparty | E1: Description | F1: Amount (USD) | G1: Balance (USD)
A2: 2025-01-07 | B2: Checking ••6538 | C2: Incoming wire (domestic) | D2: K2 OFFERS LLC | E2: AFFILIATE PAYMENT | F2: 2250 | G2: =Summary!D2+F2 -> 13303.84
A3: 2025-03-13 | B3: Checking ••6538 | C3: Outgoing payment | D3: Google LLC | E3: Invoice No. 5198439717 · your label: Google CL | F3: -16.58 | G3: =G2+F3 -> 13287.26
A4: 2025-03-24 | B4: Checking ••6538 | C4: Outgoing payment | D4: Books & Counts LLC | E4: ITR GCALIT LLC Filed by RAUNAC · your label: Raunac CA | F4: -90 | G4: =G3+F4 -> 13197.26
A5: 2025-03-26 | B5: Checking ••6538 | C5: Incoming wire (domestic) | D5: BUYGOODS INC. | E5: AFFILIATE PAYMENT | F5: 3788.14 | G5: =G4+F5 -> 16985.4
A6: 2025-04-02 | B6: Checking ••6538 | C6: Incoming wire (domestic) | D6: BUYGOODS INC. | E6: AFFILIATE PAYMENT | F6: 8548.04 | G6: =G5+F6 -> 25533.44
A7: 2025-04-04 | B7: Checking ••6538 | C7: Incoming wire (international) | D7: CLICKSTACK LTD. | E7: /URI/VENDOR PAYMENT///ROC/WW25040367291259 | F7: 1340 | G7: =G6+F7 -> 26873.44
A8: 2025-04-07 | B8: Checking ••6538 | C8: Incoming wire (domestic) | D8: BUYGOODS INC. | E8: AFFILIATE PAYMENT | F8: 2123.8 | G8: =G7+F8 -> 28997.24
A9: 2025-04-21 | B9: Checking ••6538 | C9: Outgoing payment | D9: Google LLC | E9: Send Money transaction initiated on Mercury · your label: Google CL | F9: -1.08 | G9: =G8+F9 -> 28996.16
A10: 2025-04-21 | B10: Checking ••6538 | C10: ACH / internal | D10: GOOGLE | E10: GOOGLE; ACCTVERIFY; GCALIT LLC | F10: 0.04 | G10: =G9+F10 -> 28996.2
A11: 2025-06-27 | B11: Checking ••6538 | C11: ACH / internal | D11: Guru Media Int L | E11: NTE*OBI*Affiliate Marketing Commission\ | F11: 327 | G11: =G10+F11 -> 29323.2
A12: 2025-06-30 | B12: Checking ••6538 | C12: Outgoing payment | D12: Google LLC | E12: Invoice number: 5276703039; Invoice Number - 5276703039 Invoice Date - May 31, 2025 Billing ID - 8327-3971-0682 Account ID - 405-199-0952 · your label: Google CL | F12: -6.44 | G12: =G11+F12 -> 29316.76
A13: 2025-07-02 | B13: Checking ••6538 | C13: Outgoing payment | D13: Google LLC | E13: Invoice Payment 5300675820; Invoice Number - 5300675820 Invoice Date - June 30, 2025 Billing ID - 8327-3971-0682 Account ID - 405-199-0952 · your label: Google CL | F13: -2398.97 | G13: =G12+F13 -> 26917.79
A14: 2025-07-09 | B14: Checking ••6538 | C14: Incoming wire (domestic) | D14: BUYGOODS INC. | E14: AFFILIATE PAYMENT | F14: 6347.78 | G14: =G13+F14 -> 33265.57
A15: 2025-07-12 | B15: Checking ••6538 | C15: Sent to card | D15: Mercury Credit | E15: IO AUTOPAY | F15: -241.25 | G15: =G14+F15 -> 33024.32
A16: 2025-07-12 | B16: Checking ••6538 | C16: ACH / internal | D16: Mercury IO Cashback | F16: 3.61 | G16: =G15+F16 -> 33027.93
A17: 2025-07-17 | B17: Checking ••6538 | C17: Incoming wire (domestic) | D17: SANITY ADS LIMITED | F17: 1380 | G17: =G16+F17 -> 34407.93
A18: 2025-07-31 | B18: Checking ••6538 | C18: Incoming wire (international) | D18: CLICKSTACK LTD. | E18: VENDOR PAYMENT | F18: 750 | G18: =G17+F18 -> 35157.93
A19: 2025-08-04 | B19: Checking ••6538 | C19: Outgoing payment | D19: Google LLC | E19: Invoice number: 5331260440; Invoice Number - 5331260440 Invoice Date - July 31, 2025 Billing ID - 8327-3971-0682 Account ID - GCALIT1-4 · your label: Google CL | F19: -6600.54 | G19: =G18+F19 -> 28557.39
A20: 2025-08-13 | B20: Checking ••6538 | C20: ACH / internal | D20: GOOGLE | E20: GOOGLE; ACCTVERIFY; GCALIT LLC | F20: 0.69 | G20: =G19+F20 -> 28558.08
A21: 2025-08-22 | B21: Checking ••6538 | C21: ACH / internal | D21: GOOGLE | E21: GOOGLE; YOUTUBE_PA; GCALIT LLC | F21: 182.49 | G21: =G20+F21 -> 28740.57
A22: 2025-08-27 | B22: Checking ••6538 | C22: Incoming wire (domestic) | D22: BLUE WAVE ADS LIMITED ZHONG GUO NEI | F22: 1960 | G22: =G21+F22 -> 30700.57
A23: 2025-09-03 | B23: Checking ••6538 | C23: Incoming wire (domestic) | D23: SANITY ADS LIMITED | F23: 1220 | G23: =G22+F23 -> 31920.57
A24: 2025-09-03 | B24: Checking ••6538 | C24: Outgoing payment | D24: Google LLC | E24: AUG 31,2025 -5353915159; Vendor: Invoice Number - 5353915159 Invoice Date - Aug 31, 2025 Billing ID - 8327-3971-0682 Account ID - GCALIT1-6 · your label: Google CL | F24: -2359.96 | G24: =G23+F24 -> 29560.61
A25: 2025-09-10 | B25: Checking ••6538 | C25: Incoming wire (domestic) | D25: BLITZADS LIMITED | F25: 2335 | G25: =G24+F25 -> 31895.61
A26: 2025-09-17 | B26: Checking ••6538 | C26: Incoming wire (domestic) | D26: SANITY ADS LIMITED | F26: 2215 | G26: =G25+F26 -> 34110.61
A27: 2025-09-22 | B27: Checking ••6538 | C27: ACH / internal | D27: GOOGLE | E27: GOOGLE; YOUTUBE_PA; GCALIT LLC | F27: 138.02 | G27: =G26+F27 -> 34248.63
A28: 2025-10-03 | B28: Checking ••6538 | C28: Outgoing payment | D28: Google LLC | E28: For 5377217442 Sept; Vendor: Invoice Number - 5377217442 Invoice Date - Sep 30, 2025 Billing ID - 8327-3971-0682 Account ID - GCALIT2,3,4,6 · your label: Google CL | F28: -3774.6 | G28: =G27+F28 -> 30474.03
A29: 2025-10-21 | B29: Checking ••6538 | C29: ACH / internal | D29: GOOGLE | E29: GOOGLE; YOUTUBE_PA; GCALIT LLC | F29: 141.39 | G29: =G28+F29 -> 30615.42
A30: 2025-11-12 | B30: Checking ••6538 | C30: Sent to card | D30: Mercury Credit | E30: IO AUTOPAY | F30: -80.9 | G30: =G29+F30 -> 30534.52
A31: 2025-11-12 | B31: Checking ••6538 | C31: ACH / internal | D31: Mercury IO Cashback | F31: 1.21 | G31: =G30+F31 -> 30535.73
A32: 2025-11-21 | B32: Checking ••6538 | C32: ACH / internal | D32: GOOGLE | E32: GOOGLE; YOUTUBE_PA; GCALIT LLC | F32: 177.84 | G32: =G31+F32 -> 30713.57
A33: 2025-12-02 | B33: Checking ••6538 | C33: Outgoing payment | D33: Google LLC | E33: via mercury.com; Vendor: Invoice Number - 5430635554 Invoice Date - Nov 30, 2025 Billing ID - 8327-3971-0682 Account ID - GCALIT7 · your label: Google CL | F33: -93.06 | G33: =G32+F33 -> 30620.51
A34: 2025-12-31 | B34: Checking ••6538 | C34: Incoming wire (domestic) | D34: BLITZADS LIMITED | F34: 1500 | G34: =G33+F34 -> 32120.51

Sheet Card
A1: Posted | B1: Merchant / counterparty | C1: Description | D1: Type | E1: Amount (USD)
A2: 2025-07-02 | B2: Cs* Wyomingllcattorney | C2: CS* WYOMINGLLCATTORNEY | D2: Spend | E2: -179
A3: 2025-07-02 | B3: Cs* State of Wyoming | C3: CS* STATE OF WYOMING | D3: Spend | E3: -62.25
A4: 2025-07-12 | B4: Mercury Checking ••6538 | C4: IO AUTOPAY | D4: Payment received from the bank | E4: 241.25
A5: 2025-10-16 | B5: Namecheap | C5: NAME-CHEAP.COM* MRTUUU | D5: Spend | E5: -80.9
A6: 2025-11-12 | B6: Mercury Checking ••6538 | C6: IO AUTOPAY | D6: Payment received from the bank | E6: 80.9
A8: TOTAL CARD SPEND | B8: Purchases charged to the card during 2025 | E8: -322.15
A9: TOTAL REFUNDS | B9: Merchant refunds credited back to the card | E9: 0
A10: PAID OFF FROM THE BANK ACCOUNT | B10: Mirrors the 'Sent to card' rows on the bank ledger | E10: 322.15
A11: CARD BALANCE OWED, 31 DECEMBER 2025 | B11: Spend less refunds less payments | E11: =E8+E9+E10 -> 0
A13: Card liability, 1 January 2025 | B13: Account opened 2025-05-11, after the year began, so nothing could be owed on 1 January | E13: 0
A14: Card liability, 31 December 2025 | B14: Every 2025 charge was paid off, so cash and accrual agree this year. Point-in-time: the next charge landed days into 2026. | E14: 0

Sheet Reconciliation
A1: Route | B1: How it is derived | C1: Result | D1: Expected | E1: Difference | F1: Verdict
A2: A — Statement | B2: Mercury's statement for 01–31 December 2024, ending balance | C2: 11053.84 | D2: 11053.84 | E2: 0 | F2: AUTHORITY (opening)
A3: B — Statement | B3: Mercury's statement for 01–31 December 2025, ending balance | C3: 32120.51 | D3: 32120.51 | E3: 0 | F3: AUTHORITY (closing)
A4: C — Back-computed | B4: Live balance today less every transaction posted after 31 December 2025 | C4: 32120.51 | D4: 32120.51 | E4: 0 | F4: MATCH
A5: D — Forward | B5: Opening balance plus every transaction posted inside 2025 | C5: 32120.51 | D5: 32120.51 | E5: 0 | F5: MATCH
A6: E — From account opening | B6: Every transaction from the day the account opened to 31 December 2024 | C6: 11053.84 | D6: 11053.84 | E6: 0 | F6: MATCH
A7: F — Monthly | B7: Each of the 12 months against its own statement | F7: 12 of 12 MATCH
A8: G — Peak, second route | B8: Peak recomputed as a day-cut sum rather than a running total | C8: 35157.93 | D8: 35157.93 | E8: 0 | F8: MATCH
A10: EVIDENCE | B10: Each line below is computed from the raw Mercury data, not asserted
A11: Statement / ledger bijection | B11: Transaction ids named on Mercury's 2025 statements against the ids in our pull | F11: 33 ↔ 33 — 0 missing, 0 orphan
A12: createdAt vs postedAt | B12: The trap that puts a transaction in the wrong year — tested directly, not by comparing two pulls | F12: 0 straddle the year, 5 straddle a day
A13: Rows dropped from the year | B13: Rows excluded because they failed or never posted | F13: NONE — all 38 rows posted
A14: Savings ••7355 | B14: Every one of its 12 statement ending balances in 2025 | C14: 0 | D14: 0 | E14: 0 | F14: ZERO ALL YEAR — no transactions
A15: Card payments mirrored | B15: Each 'Sent to card' row on the bank matched to its credit on the card ledger | F15: 2 of 2 PAIRED
A16: Money-out split | B16: Expenses plus sent-to-card must equal the total, not undercut it | C16: -15663.38 | D16: -15663.38 | E16: 0 | F16: MATCH
A17: Peak sits inside the year | B17: The peak must be at least the opening and at least the closing | C17: 35157.93 | D17: 32120.51 | E17: 3037.42 | F17: MATCH
A18: Year-boundary margin, opening | B18: Hours to the nearest transaction either side of 1 Jan 2025 | F18: 163.57 hours
A19: Year-boundary margin, closing | B19: Hours to the nearest transaction either side of 1 Jan 2026 | F19: 12.01 hours — wider than any timezone
A21: NOTED, NOT RESOLVED
A22: The peak DATE is clock-sensitive | B22: The credit that set it posted 2.03 h before midnight UTC. The amount is clock-independent; on IST (+5:30) the date reads 1 August. | F22: 31 July is the bank's own UTC basis
A23: Peak is an end-of-day figure | B23: A bank reports at each day's close. The intra-day high in Mercury's posting order is the same $35,157.93. | F23: changes nothing this year
A24: 'Sent to card' is not card spend | B24: Cash moved to settle the card, versus what the card bought. Equal this year only because the card was cleared in-year. | F24: see 'Total expense incurred', Summary
A25: Credit account has no statements | B25: Mercury issues statements for the two bank accounts only; the card ledger rests on the mirrored payments and its zero balance. | F25: open

Sheet Accounts
A1: Account | B1: Kind | C1: Opened | D1: Opening 1 Jan 2025 | E1: Closing 31 Dec 2025 | F1: Change | G1: Balance today
A2: Mercury Checking ••6538 | B2: checking | C2: 2024-08-07 | D2: 11053.84 | E2: 32120.51 | F2: 21066.67 | G2: 35322.1
A3: Mercury Savings ••7355 | B3: savings | C3: 2024-08-07 | D3: 0 | E3: 0 | F3: 0 | G3: 0
A4: Mercury IO credit card | B4: credit card | C4: 2025-05-11 | E4: 0 | G4: 0
B5: did not exist on 1 January 2025 — opened 11 May 2025
A7: TOTAL BANK BALANCE | B7: Checking and savings; the card is a liability, not a balance | D7: =SUM(D2:D4) -> 11053.84 | E7: =SUM(E2:E4) -> 32120.51 | F7: =SUM(F2:F4) -> 21066.67 | G7: =SUM(G2:G3) -> 35322.1
A9: Legal name | B9: GCALIT LLC
A10: EIN | B10: 61-2005202
A11: Registered address | B11: 1309 Coffeen Avenue, Ste 1200, Sheridan WY, 82801
A12: Routing number | B12: Held by Mercury; deliberately not published on this page
A13: Data pulled | B13: 2026-08-28 from the Mercury API, read-only. All dates UTC.
